2021-01-29 04:38:08,324 - ERRO - NAO AUTORIZADO
Traceback (most recent call last):
  File "C:\Users\caiom\Documents\GitHub\PhiloBot-Test-ENV\TWITTER_TEST_ENV\Posting\posting.py", line 79, in posting
    self.tweets_conta = self.obter_tweets(self.api, random_conta)
  File "C:\Users\caiom\Documents\GitHub\PhiloBot-Test-ENV\TWITTER_TEST_ENV\Posting\posting.py", line 41, in obter_tweets
    self.results = api.user_timeline(screen_name=USERNAME_ACCOUNT,
  File "C:\Users\caiom\Documents\GitHub\PhiloBot-Test-ENV\TWITTER_TEST_ENV\lib\site-packages\tweepy\binder.py", line 252, in _call
    return method.execute()
  File "C:\Users\caiom\Documents\GitHub\PhiloBot-Test-ENV\TWITTER_TEST_ENV\lib\site-packages\tweepy\binder.py", line 234, in execute
    raise TweepError(error_msg, resp, api_code=api_error_code)
tweepy.error.TweepError: Not authorized.
2021-01-29 04:38:08,354 - Not authorized.
Traceback (most recent call last):
  File "C:\Users\caiom\Documents\GitHub\PhiloBot-Test-ENV\TWITTER_TEST_ENV\Posting\posting.py", line 79, in posting
    self.tweets_conta = self.obter_tweets(self.api, random_conta)
  File "C:\Users\caiom\Documents\GitHub\PhiloBot-Test-ENV\TWITTER_TEST_ENV\Posting\posting.py", line 41, in obter_tweets
    self.results = api.user_timeline(screen_name=USERNAME_ACCOUNT,
  File "C:\Users\caiom\Documents\GitHub\PhiloBot-Test-ENV\TWITTER_TEST_ENV\lib\site-packages\tweepy\binder.py", line 252, in _call
    return method.execute()
  File "C:\Users\caiom\Documents\GitHub\PhiloBot-Test-ENV\TWITTER_TEST_ENV\lib\site-packages\tweepy\binder.py", line 234, in execute
    raise TweepError(error_msg, resp, api_code=api_error_code)
tweepy.error.TweepError: Not authorized.
