2021-01-08 22:23:41,338 - [{'code': 144, 'message': 'No status found with that ID.'}]
Traceback (most recent call last):
  File "C:\Users\rodri\PycharmProjects\PhiloBot-TWITTER\PhilosopherBOT-TWITTER-V2.5.3\PhiloBot-Test-ENV\TWITTER_TEST_ENV\Hashtag\hashtag.py", line 162, in philobot_engine
    pegando_status = api.get_status(lastid, tweet_mode='extended', include_entities=False)._json['full_text']
  File "C:\Users\rodri\AppData\Local\Programs\Python\Python38\lib\site-packages\tweepy\binder.py", line 252, in _call
    return method.execute()
  File "C:\Users\rodri\AppData\Local\Programs\Python\Python38\lib\site-packages\tweepy\binder.py", line 234, in execute
    raise TweepError(error_msg, resp, api_code=api_error_code)
tweepy.error.TweepError: [{'code': 144, 'message': 'No status found with that ID.'}]
2021-01-08 22:23:41,371 - FALHA NA PEGA DO ID - TWEET DELETADO
Traceback (most recent call last):
  File "C:\Users\rodri\PycharmProjects\PhiloBot-TWITTER\PhilosopherBOT-TWITTER-V2.5.3\PhiloBot-Test-ENV\TWITTER_TEST_ENV\Hashtag\hashtag.py", line 162, in philobot_engine
    pegando_status = api.get_status(lastid, tweet_mode='extended', include_entities=False)._json['full_text']
  File "C:\Users\rodri\AppData\Local\Programs\Python\Python38\lib\site-packages\tweepy\binder.py", line 252, in _call
    return method.execute()
  File "C:\Users\rodri\AppData\Local\Programs\Python\Python38\lib\site-packages\tweepy\binder.py", line 234, in execute
    raise TweepError(error_msg, resp, api_code=api_error_code)
tweepy.error.TweepError: [{'code': 144, 'message': 'No status found with that ID.'}]
2021-01-08 22:23:41,371 - Voltando a ouvir tweets...
Traceback (most recent call last):
  File "C:\Users\rodri\PycharmProjects\PhiloBot-TWITTER\PhilosopherBOT-TWITTER-V2.5.3\PhiloBot-Test-ENV\TWITTER_TEST_ENV\Hashtag\hashtag.py", line 162, in philobot_engine
    pegando_status = api.get_status(lastid, tweet_mode='extended', include_entities=False)._json['full_text']
  File "C:\Users\rodri\AppData\Local\Programs\Python\Python38\lib\site-packages\tweepy\binder.py", line 252, in _call
    return method.execute()
  File "C:\Users\rodri\AppData\Local\Programs\Python\Python38\lib\site-packages\tweepy\binder.py", line 234, in execute
    raise TweepError(error_msg, resp, api_code=api_error_code)
tweepy.error.TweepError: [{'code': 144, 'message': 'No status found with that ID.'}]
2021-01-08 22:23:41,372 - Escutando tweets da Hashtag: #TestePhilo....
Traceback (most recent call last):
  File "C:\Users\rodri\PycharmProjects\PhiloBot-TWITTER\PhilosopherBOT-TWITTER-V2.5.3\PhiloBot-Test-ENV\TWITTER_TEST_ENV\Hashtag\hashtag.py", line 162, in philobot_engine
    pegando_status = api.get_status(lastid, tweet_mode='extended', include_entities=False)._json['full_text']
  File "C:\Users\rodri\AppData\Local\Programs\Python\Python38\lib\site-packages\tweepy\binder.py", line 252, in _call
    return method.execute()
  File "C:\Users\rodri\AppData\Local\Programs\Python\Python38\lib\site-packages\tweepy\binder.py", line 234, in execute
    raise TweepError(error_msg, resp, api_code=api_error_code)
tweepy.error.TweepError: [{'code': 144, 'message': 'No status found with that ID.'}]
2021-01-08 22:26:34,271 - [{'code': 144, 'message': 'No status found with that ID.'}]
Traceback (most recent call last):
  File "C:\Users\rodri\PycharmProjects\PhiloBot-TWITTER\PhilosopherBOT-TWITTER-V2.5.3\PhiloBot-Test-ENV\TWITTER_TEST_ENV\Hashtag\hashtag.py", line 162, in philobot_engine
    pegando_status = api.get_status(lastid, tweet_mode='extended', include_entities=False)._json['full_text']
  File "C:\Users\rodri\AppData\Local\Programs\Python\Python38\lib\site-packages\tweepy\binder.py", line 252, in _call
    return method.execute()
  File "C:\Users\rodri\AppData\Local\Programs\Python\Python38\lib\site-packages\tweepy\binder.py", line 234, in execute
    raise TweepError(error_msg, resp, api_code=api_error_code)
tweepy.error.TweepError: [{'code': 144, 'message': 'No status found with that ID.'}]
