2021-01-29 12:53:30,712 - Unable to access file: O sistema não pode encontrar o arquivo especificado
Traceback (most recent call last):
  File "C:\Users\caiom\Documents\GitHub\PhiloBot-Test-ENV\TWITTER_TEST_ENV\lib\site-packages\tweepy\api.py", line 1372, in _pack_image
    if os.path.getsize(filename) > (max_size * 1024):
  File "C:\Users\caiom\AppData\Local\Programs\Python\Python38\lib\genericpath.py", line 50, in getsize
    return os.stat(filename).st_size
FileNotFoundError: [WinError 2] O sistema não pode encontrar o arquivo especificado: 'test_img.png'

During handling of the above exception, another exception occurred:

Traceback (most recent call last):
  File "C:/Users/caiom/Documents/GitHub/PhiloBot-Test-ENV/TWITTER_TEST_ENV/main.py", line 107, in hash_or_posting
    post_status_with_media()
  File "C:\Users\caiom\Documents\GitHub\PhiloBot-Test-ENV\TWITTER_TEST_ENV\Aux_scripts\EnvironmentStatus\auto_status.py", line 12, in post_status_with_media
    api.update_with_media('test_img.png', status=status_test)
  File "C:\Users\caiom\Documents\GitHub\PhiloBot-Test-ENV\TWITTER_TEST_ENV\lib\site-packages\tweepy\api.py", line 271, in update_with_media
    headers, post_data = API._pack_image(filename, 3072,
  File "C:\Users\caiom\Documents\GitHub\PhiloBot-Test-ENV\TWITTER_TEST_ENV\lib\site-packages\tweepy\api.py", line 1376, in _pack_image
    raise TweepError('Unable to access file: %s' % e.strerror)
tweepy.error.TweepError: Unable to access file: O sistema não pode encontrar o arquivo especificado
2021-01-29 12:54:37,252 - Unable to access file: O sistema não pode encontrar o caminho especificado
Traceback (most recent call last):
  File "C:\Users\caiom\Documents\GitHub\PhiloBot-Test-ENV\TWITTER_TEST_ENV\lib\site-packages\tweepy\api.py", line 1372, in _pack_image
    if os.path.getsize(filename) > (max_size * 1024):
  File "C:\Users\caiom\AppData\Local\Programs\Python\Python38\lib\genericpath.py", line 50, in getsize
    return os.stat(filename).st_size
FileNotFoundError: [WinError 3] O sistema não pode encontrar o caminho especificado: 'TWITTER_TEST_ENV/Aux_scripts/EnvironmentStatus/test_img.png'

During handling of the above exception, another exception occurred:

Traceback (most recent call last):
  File "C:/Users/caiom/Documents/GitHub/PhiloBot-Test-ENV/TWITTER_TEST_ENV/main.py", line 107, in hash_or_posting
    post_status_with_media()
  File "C:\Users\caiom\Documents\GitHub\PhiloBot-Test-ENV\TWITTER_TEST_ENV\Aux_scripts\EnvironmentStatus\auto_status.py", line 12, in post_status_with_media
    api.update_with_media('TWITTER_TEST_ENV/Aux_scripts/EnvironmentStatus/test_img.png', status=status_test)
  File "C:\Users\caiom\Documents\GitHub\PhiloBot-Test-ENV\TWITTER_TEST_ENV\lib\site-packages\tweepy\api.py", line 271, in update_with_media
    headers, post_data = API._pack_image(filename, 3072,
  File "C:\Users\caiom\Documents\GitHub\PhiloBot-Test-ENV\TWITTER_TEST_ENV\lib\site-packages\tweepy\api.py", line 1376, in _pack_image
    raise TweepError('Unable to access file: %s' % e.strerror)
tweepy.error.TweepError: Unable to access file: O sistema não pode encontrar o caminho especificado
2021-01-29 13:50:11,834 - File is too big, must be less than 3072kb.
Traceback (most recent call last):
  File "C:/Users/caiom/Documents/GitHub/PhiloBot-Test-ENV/TWITTER_TEST_ENV/main.py", line 110, in hash_or_posting
    AUTO_post_status_with_media(IMG_PATH=IMG_PATH)
  File "C:\Users\caiom\Documents\GitHub\PhiloBot-Test-ENV\TWITTER_TEST_ENV\Aux_scripts\EnvironmentStatus\auto_status.py", line 32, in AUTO_post_status_with_media
    api.update_with_media(IMG_PATH, status=f'#Testemaker {status_key}')
  File "C:\Users\caiom\Documents\GitHub\PhiloBot-Test-ENV\TWITTER_TEST_ENV\lib\site-packages\tweepy\api.py", line 271, in update_with_media
    headers, post_data = API._pack_image(filename, 3072,
  File "C:\Users\caiom\Documents\GitHub\PhiloBot-Test-ENV\TWITTER_TEST_ENV\lib\site-packages\tweepy\api.py", line 1373, in _pack_image
    raise TweepError('File is too big, must be less than %skb.'
tweepy.error.TweepError: File is too big, must be less than 3072kb.
2021-01-29 19:37:50,752 - [{'message': 'Application cannot perform write actions. Contact Twitter Platform Operations through https://help.twitter.com/forms/platform.', 'code': 261}]
Traceback (most recent call last):
  File "C:\Users\rodri\PythonProjects\PhiloBot-Test-ENV\TWITTER_TEST_ENV\main.py", line 113, in hash_or_posting
    AUTO_post_status_with_media(IMG_PATH=IMG_PATH)
  File "C:\Users\rodri\PythonProjects\PhiloBot-Test-ENV\TWITTER_TEST_ENV\Aux_scripts\EnvironmentStatus\auto_status.py", line 32, in AUTO_post_status_with_media
    api.update_with_media(IMG_PATH, status=f'#Testemaker {status_key}' + ' @felipeneto')
  File "C:\Users\rodri\AppData\Local\Programs\Python\Python39\lib\site-packages\tweepy\api.py", line 283, in update_with_media
    return bind_api(
  File "C:\Users\rodri\AppData\Local\Programs\Python\Python39\lib\site-packages\tweepy\binder.py", line 253, in _call
    return method.execute()
  File "C:\Users\rodri\AppData\Local\Programs\Python\Python39\lib\site-packages\tweepy\binder.py", line 234, in execute
    raise TweepError(error_msg, resp, api_code=api_error_code)
tweepy.error.TweepError: [{'message': 'Application cannot perform write actions. Contact Twitter Platform Operations through https://help.twitter.com/forms/platform.', 'code': 261}]
2021-01-29 19:43:45,695 - Read-only application cannot POST.
Traceback (most recent call last):
  File "C:\Users\rodri\PythonProjects\PhiloBot-Test-ENV\TWITTER_TEST_ENV\main.py", line 113, in hash_or_posting
    AUTO_post_status_with_media(IMG_PATH=IMG_PATH)
  File "C:\Users\rodri\PythonProjects\PhiloBot-Test-ENV\TWITTER_TEST_ENV\Aux_scripts\EnvironmentStatus\auto_status.py", line 32, in AUTO_post_status_with_media
    api.update_with_media(IMG_PATH, status=f'#Testemaker {status_key}' + ' @felipeneto')
  File "C:\Users\rodri\AppData\Local\Programs\Python\Python39\lib\site-packages\tweepy\api.py", line 283, in update_with_media
    return bind_api(
  File "C:\Users\rodri\AppData\Local\Programs\Python\Python39\lib\site-packages\tweepy\binder.py", line 253, in _call
    return method.execute()
  File "C:\Users\rodri\AppData\Local\Programs\Python\Python39\lib\site-packages\tweepy\binder.py", line 234, in execute
    raise TweepError(error_msg, resp, api_code=api_error_code)
tweepy.error.TweepError: Read-only application cannot POST.
